Workbook
Name NativeTimeline_Order_Date: #N/A
Name Slicer_Loyalty_Card: #N/A
Name Slicer_Roast_Type: #N/A
Name Slicer_Size: #N/A

Sheet RFM Analysis
A1: Snapshot Date | B1: =MAX(orders!B:B)+1 -> 44793 | E1: =PERCENTILE(D5:D917,0.2) -> 267.8 | F1: =PERCENTILE(D5:D917,0.4) -> 509.8 | G1: =PERCENTILE(D5:D917,0.6) -> 766.2 | H1: =PERCENTILE(D5:D917,0.8) -> 1040.8
A4: Customer ID | B4: Customer Name | C4: Last Order Date | D4: Recency (days) | E4: Frequency | F4: Monetary | G4: Loyalty Card | H4: R Score | I4: F Score | J4: M Score | K4: RFM Score | L4: Segment | N4: Segment | O4: Count
A5: 00246-15080-LE | B5: =INDEX(orders!$F:$F,MATCH(A5,orders!$C:$C,0)) -> Francesco Dressel | C5: =_xlfn.MAXIFS(orders!$B:$B,orders!$C:$C,A5) -> 44754 | D5: =$B$1-C5 -> 39 | E5: =COUNTIFS(orders!$C:$C,A5) -> 1 | F5: =SUMIFS(orders!$M:$M,orders!$C:$C,A5) -> 178.71 | G5: =INDEX(orders!$P:$P,MATCH(A5,orders!$C:$C,0)) -> No | H5: =IF(D5<=$E$1,5,IF(D5<=$F$1,4,IF(D5<=$G$1,3,IF(D5<=$H$1,2,1)))) -> 5 | I5: =IF(E5<=1,1,IF(E5<=2,3,5)) -> 1 | J5: =IF(F5<=PERCENTILE($F$5:$F$917,0.2),1,IF(F5<=PERCENTILE($F$5:$F$917,0.4),2,IF(F5<=PERCENTILE($F$5:$F$917,0.6),3,IF(F5<=PERCENTILE($F$5:$F$917,0.8),4,5)))) -> 5 | K5: =H5+I5+J5 -> 11 | L5: =IF(AND(E5>=2,H5>=4),"Loyal Repeat Customers",IF(E5>=2,"At-Risk Repeat Customers",IF(AND(H5>=4,J5>=4),"Recent High-Value (One-Time)",IF(H5<=2,"Lapsed One-Time Buyers","Standard One-Time Buyers")))) -> Recent High-Value (One-Time) | N5: Loyal Repeat Customers | O5: =COUNTIF($L$5:$L$917,N5) -> 33
A6: 00256-19905-YG | B6: =INDEX(orders!$F:$F,MATCH(A6,orders!$C:$C,0)) -> Stanislaus Valsler | C6: =_xlfn.MAXIFS(orders!$B:$B,orders!$C:$C,A6) -> 43484 | D6: =$B$1-C6 -> 1309 | E6: =COUNTIFS(orders!$C:$C,A6) -> 1 | F6: =SUMIFS(orders!$M:$M,orders!$C:$C,A6) -> 40.5 | G6: =INDEX(orders!$P:$P,MATCH(A6,orders!$C:$C,0)) -> No | H6: =IF(D6<=$E$1,5,IF(D6<=$F$1,4,IF(D6<=$G$1,3,IF(D6<=$H$1,2,1)))) -> 1 | I6: =IF(E6<=1,1,IF(E6<=2,3,5)) -> 1 | J6: =IF(F6<=PERCENTILE($F$5:$F$917,0.2),1,IF(F6<=PERCENTILE($F$5:$F$917,0.4),2,IF(F6<=PERCENTILE($F$5:$F$917,0.6),3,IF(F6<=PERCENTILE($F$5:$F$917,0.8),4,5)))) -> 3 | K6: =H6+I6+J6 -> 5 | L6: =IF(AND(E6>=2,H6>=4),"Loyal Repeat Customers",IF(E6>=2,"At-Risk Repeat Customers",IF(AND(H6>=4,J6>=4),"Recent High-Value (One-Time)",IF(H6<=2,"Lapsed One-Time Buyers","Standard One-Time Buyers")))) -> Lapsed One-Time Buyers | N6: At-Risk Repeat Customers | O6: =COUNTIF($L$5:$L$917,N6) -> 19
A7: 00445-42781-KX | B7: =INDEX(orders!$F:$F,MATCH(A7,orders!$C:$C,0)) -> Faunie Brigham | C7: =_xlfn.MAXIFS(orders!$B:$B,orders!$C:$C,A7) -> 44680 | D7: =$B$1-C7 -> 113 | E7: =COUNTIFS(orders!$C:$C,A7) -> 4 | F7: =SUMIFS(orders!$M:$M,orders!$C:$C,A7) -> 163.72 | G7: =INDEX(orders!$P:$P,MATCH(A7,orders!$C:$C,0)) -> Yes | H7: =IF(D7<=$E$1,5,IF(D7<=$F$1,4,IF(D7<=$G$1,3,IF(D7<=$H$1,2,1)))) -> 5 | I7: =IF(E7<=1,1,IF(E7<=2,3,5)) -> 5 | J7: =IF(F7<=PERCENTILE($F$5:$F$917,0.2),1,IF(F7<=PERCENTILE($F$5:$F$917,0.4),2,IF(F7<=PERCENTILE($F$5:$F$917,0.6),3,IF(F7<=PERCENTILE($F$5:$F$917,0.8),4,5)))) -> 5 | K7: =H7+I7+J7 -> 15 | L7: =IF(AND(E7>=2,H7>=4),"Loyal Repeat Customers",IF(E7>=2,"At-Risk Repeat Customers",IF(AND(H7>=4,J7>=4),"Recent High-Value (One-Time)",IF(H7<=2,"Lapsed One-Time Buyers","Standard One-Time Buyers")))) -> Loyal Repeat Customers | N7: Recent High-Value (One-Time) | O7: =COUNTIF($L$5:$L$917,N7) -> 129
A8: 00539-42510-RY | B8: =INDEX(orders!$F:$F,MATCH(A8,orders!$C:$C,0)) -> Nickey Youles | C8: =_xlfn.MAXIFS(orders!$B:$B,orders!$C:$C,A8) -> 43891 | D8: =$B$1-C8 -> 902 | E8: =COUNTIFS(orders!$C:$C,A8) -> 1 | F8: =SUMIFS(orders!$M:$M,orders!$C:$C,A8) -> 148.925 | G8: =INDEX(orders!$P:$P,MATCH(A8,orders!$C:$C,0)) -> Yes | H8: =IF(D8<=$E$1,5,IF(D8<=$F$1,4,IF(D8<=$G$1,3,IF(D8<=$H$1,2,1)))) -> 2 | I8: =IF(E8<=1,1,IF(E8<=2,3,5)) -> 1 | J8: =IF(F8<=PERCENTILE($F$5:$F$917,0.2),1,IF(F8<=PERCENTILE($F$5:$F$917,0.4),2,IF(F8<=PERCENTILE($F$5:$F$917,0.6),3,IF(F8<=PERCENTILE($F$5:$F$917,0.8),4,5)))) -> 5 | K8: =H8+I8+J8 -> 8 | L8: =IF(AND(E8>=2,H8>=4),"Loyal Repeat Customers",IF(E8>=2,"At-Risk Repeat Customers",IF(AND(H8>=4,J8>=4),"Recent High-Value (One-Time)",IF(H8<=2,"Lapsed One-Time Buyers","Standard One-Time Buyers")))) -> Lapsed One-Time Buyers | N8: Lapsed One-Time Buyers | O8: =COUNTIF($L$5:$L$917,N8) -> 351
A9: 00852-54571-WP | B9: =INDEX(orders!$F:$F,MATCH(A9,orders!$C:$C,0)) -> De Drewitt | C9: =_xlfn.MAXIFS(orders!$B:$B,orders!$C:$C,A9) -> 44387 | D9: =$B$1-C9 -> 406 | E9: =COUNTIFS(orders!$C:$C,A9) -> 1 | F9: =SUMIFS(orders!$M:$M,orders!$C:$C,A9) -> 8.25 | G9: =INDEX(orders!$P:$P,MATCH(A9,orders!$C:$C,0)) -> Yes | H9: =IF(D9<=$E$1,5,IF(D9<=$F$1,4,IF(D9<=$G$1,3,IF(D9<=$H$1,2,1)))) -> 4 | I9: =IF(E9<=1,1,IF(E9<=2,3,5)) -> 1 | J9: =IF(F9<=PERCENTILE($F$5:$F$917,0.2),1,IF(F9<=PERCENTILE($F$5:$F$917,0.4),2,IF(F9<=PERCENTILE($F$5:$F$917,0.6),3,IF(F9<=PERCENTILE($F$5:$F$917,0.8),4,5)))) -> 1 | K9: =H9+I9+J9 -> 6 | L9: =IF(AND(E9>=2,H9>=4),"Loyal Repeat Customers",IF(E9>=2,"At-Risk Repeat Customers",IF(AND(H9>=4,J9>=4),"Recent High-Value (One-Time)",IF(H9<=2,"Lapsed One-Time Buyers","Standard One-Time Buyers")))) -> Standard One-Time Buyers | N9: Standard One-Time Buyers | O9: =COUNTIF($L$5:$L$917,N9) -> 381
A10: 00886-35803-FG | B10: =INDEX(orders!$F:$F,MATCH(A10,orders!$C:$C,0)) -> Edeline Edney | C10: =_xlfn.MAXIFS(orders!$B:$B,orders!$C:$C,A10) -> 43719 | D10: =$B$1-C10 -> 1074 | E10: =COUNTIFS(orders!$C:$C,A10) -> 1 | F10: =SUMIFS(orders!$M:$M,orders!$C:$C,A10) -> 23.31 | G10: =INDEX(orders!$P:$P,MATCH(A10,orders!$C:$C,0)) -> No | H10: =IF(D10<=$E$1,5,IF(D10<=$F$1,4,IF(D10<=$G$1,3,IF(D10<=$H$1,2,1)))) -> 1 | I10: =IF(E10<=1,1,IF(E10<=2,3,5)) -> 1 | J10: =IF(F10<=PERCENTILE($F$5:$F$917,0.2),1,IF(F10<=PERCENTILE($F$5:$F$917,0.4),2,IF(F10<=PERCENTILE($F$5:$F$917,0.6),3,IF(F10<=PERCENTILE($F$5:$F$917,0.8),4,5)))) -> 2 | K10: =H10+I10+J10 -> 4 | L10: =IF(AND(E10>=2,H10>=4),"Loyal Repeat Customers",IF(E10>=2,"At-Risk Repeat Customers",IF(AND(H10>=4,J10>=4),"Recent High-Value (One-Time)",IF(H10<=2,"Lapsed One-Time Buyers","Standard One-Time Buyers")))) -> Lapsed One-Time Buyers
A11: 00888-74814-UZ | B11: =INDEX(orders!$F:$F,MATCH(A11,orders!$C:$C,0)) -> Theresita Newbury | C11: =_xlfn.MAXIFS(orders!$B:$B,orders!$C:$C,A11) -> 44775 | D11: =$B$1-C11 -> 18 | E11: =COUNTIFS(orders!$C:$C,A11) -> 1 | F11: =SUMIFS(orders!$M:$M,orders!$C:$C,A11) -> 17.91 | G11: =INDEX(orders!$P:$P,MATCH(A11,orders!$C:$C,0)) -> No | H11: =IF(D11<=$E$1,5,IF(D11<=$F$1,4,IF(D11<=$G$1,3,IF(D11<=$H$1,2,1)))) -> 5 | I11: =IF(E11<=1,1,IF(E11<=2,3,5)) -> 1 | J11: =IF(F11<=PERCENTILE($F$5:$F$917,0.2),1,IF(F11<=PERCENTILE($F$5:$F$917,0.4),2,IF(F11<=PERCENTILE($F$5:$F$917,0.6),3,IF(F11<=PERCENTILE($F$5:$F$917,0.8),4,5)))) -> 2 | K11: =H11+I11+J11 -> 8 | L11: =IF(AND(E11>=2,H11>=4),"Loyal Repeat Customers",IF(E11>=2,"At-Risk Repeat Customers",IF(AND(H11>=4,J11>=4),"Recent High-Value (One-Time)",IF(H11<=2,"Lapsed One-Time Buyers","Standard One-Time Buyers")))) -> Standard One-Time Buyers | N11: Repeat Purchase Rate by Loyalty
A12: 01035-70465-UO | B12: =INDEX(orders!$F:$F,MATCH(A12,orders!$C:$C,0)) -> Anselma Attwater | C12: =_xlfn.MAXIFS(orders!$B:$B,orders!$C:$C,A12) -> 43790 | D12: =$B$1-C12 -> 1003 | E12: =COUNTIFS(orders!$C:$C,A12) -> 2 | F12: =SUMIFS(orders!$M:$M,orders!$C:$C,A12) -> 71.7 | G12: =INDEX(orders!$P:$P,MATCH(A12,orders!$C:$C,0)) -> Yes | H12: =IF(D12<=$E$1,5,IF(D12<=$F$1,4,IF(D12<=$G$1,3,IF(D12<=$H$1,2,1)))) -> 2 | I12: =IF(E12<=1,1,IF(E12<=2,3,5)) -> 3 | J12: =IF(F12<=PERCENTILE($F$5:$F$917,0.2),1,IF(F12<=PERCENTILE($F$5:$F$917,0.4),2,IF(F12<=PERCENTILE($F$5:$F$917,0.6),3,IF(F12<=PERCENTILE($F$5:$F$917,0.8),4,5)))) -> 4 | K12: =H12+I12+J12 -> 9 | L12: =IF(AND(E12>=2,H12>=4),"Loyal Repeat Customers",IF(E12>=2,"At-Risk Repeat Customers",IF(AND(H12>=4,J12>=4),"Recent High-Value (One-Time)",IF(H12<=2,"Lapsed One-Time Buyers","Standard One-Time Buyers")))) -> At-Risk Repeat Customers | N12: Loyalty Card | O12: Repeat Rate %
A13: 01282-28364-RZ | B13: =INDEX(orders!$F:$F,MATCH(A13,orders!$C:$C,0)) -> Koressa O'Geneay | C13: =_xlfn.MAXIFS(orders!$B:$B,orders!$C:$C,A13) -> 44561 | D13: =$B$1-C13 -> 232 | E13: =COUNTIFS(orders!$C:$C,A13) -> 1 | F13: =SUMIFS(orders!$M:$M,orders!$C:$C,A13) -> 47.8 | G13: =INDEX(orders!$P:$P,MATCH(A13,orders!$C:$C,0)) -> No | H13: =IF(D13<=$E$1,5,IF(D13<=$F$1,4,IF(D13<=$G$1,3,IF(D13<=$H$1,2,1)))) -> 5 | I13: =IF(E13<=1,1,IF(E13<=2,3,5)) -> 1 | J13: =IF(F13<=PERCENTILE($F$5:$F$917,0.2),1,IF(F13<=PERCENTILE($F$5:$F$917,0.4),2,IF(F13<=PERCENTILE($F$5:$F$917,0.6),3,IF(F13<=PERCENTILE($F$5:$F$917,0.8),4,5)))) -> 4 | K13: =H13+I13+J13 -> 10 | L13: =IF(AND(E13>=2,H13>=4),"Loyal Repeat Customers",IF(E13>=2,"At-Risk Repeat Customers",IF(AND(H13>=4,J13>=4),"Recent High-Value (One-Time)",IF(H13<=2,"Lapsed One-Time Buyers","Standard One-Time Buyers")))) -> Recent High-Value (One-Time) | N13: No | O13: =COUNTIFS($G$5:$G$917,N13,$E$5:$E$917,">=2")/COUNTIF($G$5:$G$917,N13)*100 -> 6.5957447
A14: 01297-94364-XH | B14: =INDEX(orders!$F:$F,MATCH(A14,orders!$C:$C,0)) -> Deana Staite | C14: =_xlfn.MAXIFS(orders!$B:$B,orders!$C:$C,A14) -> 44083 | D14: =$B$1-C14 -> 710 | E14: =COUNTIFS(orders!$C:$C,A14) -> 1 | F14: =SUMIFS(orders!$M:$M,orders!$C:$C,A14) -> 17.46 | G14: =INDEX(orders!$P:$P,MATCH(A14,orders!$C:$C,0)) -> No | H14: =IF(D14<=$E$1,5,IF(D14<=$F$1,4,IF(D14<=$G$1,3,IF(D14<=$H$1,2,1)))) -> 3 | I14: =IF(E14<=1,1,IF(E14<=2,3,5)) -> 1 | J14: =IF(F14<=PERCENTILE($F$5:$F$917,0.2),1,IF(F14<=PERCENTILE($F$5:$F$917,0.4),2,IF(F14<=PERCENTILE($F$5:$F$917,0.6),3,IF(F14<=PERCENTILE($F$5:$F$917,0.8),4,5)))) -> 2 | K14: =H14+I14+J14 -> 6 | L14: =IF(AND(E14>=2,H14>=4),"Loyal Repeat Customers",IF(E14>=2,"At-Risk Repeat Customers",IF(AND(H14>=4,J14>=4),"Recent High-Value (One-Time)",IF(H14<=2,"Lapsed One-Time Buyers","Standard One-Time Buyers")))) -> Standard One-Time Buyers | N14: Yes | O14: =COUNTIFS($G$5:$G$917,N14,$E$5:$E$917,">=2")/COUNTIF($G$5:$G$917,N14)*100 -> 4.7404063
A15: 01304-59807-OB | B15: =INDEX(orders!$F:$F,MATCH(A15,orders!$C:$C,0)) -> Nico Hubert | C15: =_xlfn.MAXIFS(orders!$B:$B,orders!$C:$C,A15) -> 44076 | D15: =$B$1-C15 -> 717 | E15: =COUNTIFS(orders!$C:$C,A15) -> 1 | F15: =SUMIFS(orders!$M:$M,orders!$C:$C,A15) -> 6.75 | G15: =INDEX(orders!$P:$P,MATCH(A15,orders!$C:$C,0)) -> Yes | H15: =IF(D15<=$E$1,5,IF(D15<=$F$1,4,IF(D15<=$G$1,3,IF(D15<=$H$1,2,1)))) -> 3 | I15: =IF(E15<=1,1,IF(E15<=2,3,5)) -> 1 | J15: =IF(F15<=PERCENTILE($F$5:$F$917,0.2),1,IF(F15<=PERCENTILE($F$5:$F$917,0.4),2,IF(F15<=PERCENTILE($F$5:$F$917,0.6),3,IF(F15<=PERCENTILE($F$5:$F$917,0.8),4,5)))) -> 1 | K15: =H15+I15+J15 -> 5 | L15: =IF(AND(E15>=2,H15>=4),"Loyal Repeat Customers",IF(E15>=2,"At-Risk Repeat Customers",IF(AND(H15>=4,J15>=4),"Recent High-Value (One-Time)",IF(H15<=2,"Lapsed One-Time Buyers","Standard One-Time Buyers")))) -> Standard One-Time Buyers
A16: 01338-83217-GV | B16: =INDEX(orders!$F:$F,MATCH(A16,orders!$C:$C,0)) -> Mord Meriet | C16: =_xlfn.MAXIFS(orders!$B:$B,orders!$C:$C,A16) -> 43684 | D16: =$B$1-C16 -> 1109 | E16: =COUNTIFS(orders!$C:$C,A16) -> 1 | F16: =SUMIFS(orders!$M:$M,orders!$C:$C,A16) -> 68.655 | G16: =INDEX(orders!$P:$P,MATCH(A16,orders!$C:$C,0)) -> No | H16: =IF(D16<=$E$1,5,IF(D16<=$F$1,4,IF(D16<=$G$1,3,IF(D16<=$H$1,2,1)))) -> 1 | I16: =IF(E16<=1,1,IF(E16<=2,3,5)) -> 1 | J16: =IF(F16<=PERCENTILE($F$5:$F$917,0.2),1,IF(F16<=PERCENTILE($F$5:$F$917,0.4),2,IF(F16<=PERCENTILE($F$5:$F$917,0.6),3,IF(F16<=PERCENTILE($F$5:$F$917,0.8),4,5)))) -> 4 | K16: =H16+I16+J16 -> 6 | L16: =IF(AND(E16>=2,H16>=4),"Loyal Repeat Customers",IF(E16>=2,"At-Risk Repeat Customers",IF(AND(H16>=4,J16>=4),"Recent High-Value (One-Time)",IF(H16<=2,"Lapsed One-Time Buyers","Standard One-Time Buyers")))) -> Lapsed One-Time Buyers
A17: 01433-04270-AX | B17: =INDEX(orders!$F:$F,MATCH(A17,orders!$C:$C,0)) -> Felecia Dodgson | C17: =_xlfn.MAXIFS(orders!$B:$B,orders!$C:$C,A17) -> 43913 | D17: =$B$1-C17 -> 880 | E17: =COUNTIFS(orders!$C:$C,A17) -> 1 | F17: =SUMIFS(orders!$M:$M,orders!$C:$C,A17) -> 35.82 | G17: =INDEX(orders!$P:$P,MATCH(A17,orders!$C:$C,0)) -> Yes | H17: =IF(D17<=$E$1,5,IF(D17<=$F$1,4,IF(D17<=$G$1,3,IF(D17<=$H$1,2,1)))) -> 2 | I17: =IF(E17<=1,1,IF(E17<=2,3,5)) -> 1 | J17: =IF(F17<=PERCENTILE($F$5:$F$917,0.2),1,IF(F17<=PERCENTILE($F$5:$F$917,0.4),2,IF(F17<=PERCENTILE($F$5:$F$917,0.6),3,IF(F17<=PERCENTILE($F$5:$F$917,0.8),4,5)))) -> 3 | K17: =H17+I17+J17 -> 6 | L17: =IF(AND(E17>=2,H17>=4),"Loyal Repeat Customers",IF(E17>=2,"At-Risk Repeat Customers",IF(AND(H17>=4,J17>=4),"Recent High-Value (One-Time)",IF(H17<=2,"Lapsed One-Time Buyers","Standard One-Time Buyers")))) -> Lapsed One-Time Buyers
A18: 01474-63436-TP | B18: =INDEX(orders!$F:$F,MATCH(A18,orders!$C:$C,0)) -> Read Cutts | C18: =_xlfn.MAXIFS(orders!$B:$B,orders!$C:$C,A18) -> 44409 | D18: =$B$1-C18 -> 384 | E18: =COUNTIFS(orders!$C:$C,A18) -> 1 | F18: =SUMIFS(orders!$M:$M,orders!$C:$C,A18) -> 114.425 | G18: =INDEX(orders!$P:$P,MATCH(A18,orders!$C:$C,0)) -> No | H18: =IF(D18<=$E$1,5,IF(D18<=$F$1,4,IF(D18<=$G$1,3,IF(D18<=$H$1,2,1)))) -> 4 | I18: =IF(E18<=1,1,IF(E18<=2,3,5)) -> 1 | J18: =IF(F18<=PERCENTILE($F$5:$F$917,0.2),1,IF(F18<=PERCENTILE($F$5:$F$917,0.4),2,IF(F18<=PERCENTILE($F$5:$F$917,0.6),3,IF(F18<=PERCENTILE($F$5:$F$917,0.8),4,5)))) -> 5 | K18: =H18+I18+J18 -> 10 | L18: =IF(AND(E18>=2,H18>=4),"Loyal Repeat Customers",IF(E18>=2,"At-Risk Repeat Customers",IF(AND(H18>=4,J18>=4),"Recent High-Value (One-Time)",IF(H18<=2,"Lapsed One-Time Buyers","Standard One-Time Buyers")))) -> Recent High-Value (One-Time)
A19: 01603-43789-TN | B19: =INDEX(orders!$F:$F,MATCH(A19,orders!$C:$C,0)) -> Brice Romera | C19: =_xlfn.MAXIFS(orders!$B:$B,orders!$C:$C,A19) -> 44114 | D19: =$B$1-C19 -> 679 | E19: =COUNTIFS(orders!$C:$C,A19) -> 2 | F19: =SUMIFS(orders!$M:$M,orders!$C:$C,A19) -> 246.21 | G19: =INDEX(orders!$P:$P,MATCH(A19,orders!$C:$C,0)) -> Yes | H19: =IF(D19<=$E$1,5,IF(D19<=$F$1,4,IF(D19<=$G$1,3,IF(D19<=$H$1,2,1)))) -> 3 | I19: =IF(E19<=1,1,IF(E19<=2,3,5)) -> 3 | J19: =IF(F19<=PERCENTILE($F$5:$F$917,0.2),1,IF(F19<=PERCENTILE($F$5:$F$917,0.4),2,IF(F19<=PERCENTILE($F$5:$F$917,0.6),3,IF(F19<=PERCENTILE($F$5:$F$917,0.8),4,5)))) -> 5 | K19: =H19+I19+J19 -> 11 | L19: =IF(AND(E19>=2,H19>=4),"Loyal Repeat Customers",IF(E19>=2,"At-Risk Repeat Customers",IF(AND(H19>=4,J19>=4),"Recent High-Value (One-Time)",IF(H19<=2,"Lapsed One-Time Buyers","Standard One-Time Buyers")))) -> At-Risk Repeat Customers
A20: 01811-60350-CU | B20: =INDEX(orders!$F:$F,MATCH(A20,orders!$C:$C,0)) -> Sarette Ducarel | C20: =_xlfn.MAXIFS(orders!$B:$B,orders!$C:$C,A20) -> 44027 | D20: =$B$1-C20 -> 766 | E20: =COUNTIFS(orders!$C:$C,A20) -> 1 | F20: =SUMIFS(orders!$M:$M,orders!$C:$C,A20) -> 82.5 | G20: =INDEX(orders!$P:$P,MATCH(A20,orders!$C:$C,0)) -> No | H20: =IF(D20<=$E$1,5,IF(D20<=$F$1,4,IF(D20<=$G$1,3,IF(D20<=$H$1,2,1)))) -> 3 | I20: =IF(E20<=1,1,IF(E20<=2,3,5)) -> 1 | J20: =IF(F20<=PERCENTILE($F$5:$F$917,0.2),1,IF(F20<=PERCENTILE($F$5:$F$917,0.4),2,IF(F20<=PERCENTILE($F$5:$F$917,0.6),3,IF(F20<=PERCENTILE($F$5:$F$917,0.8),4,5)))) -> 5 | K20: =H20+I20+J20 -> 9 | L20: =IF(AND(E20>=2,H20>=4),"Loyal Repeat Customers",IF(E20>=2,"At-Risk Repeat Customers",IF(AND(H20>=4,J20>=4),"Recent High-Value (One-Time)",IF(H20<=2,"Lapsed One-Time Buyers","Standard One-Time Buyers")))) -> Standard One-Time Buyers
A21: 01841-48191-NL | B21: =INDEX(orders!$F:$F,MATCH(A21,orders!$C:$C,0)) -> Cam Jewster | C21: =_xlfn.MAXIFS(orders!$B:$B,orders!$C:$C,A21) -> 43889 | D21: =$B$1-C21 -> 904 | E21: =COUNTIFS(orders!$C:$C,A21) -> 2 | F21: =SUMIFS(orders!$M:$M,orders!$C:$C,A21) -> 46.965 | G21: =INDEX(orders!$P:$P,MATCH(A21,orders!$C:$C,0)) -> Yes | H21: =IF(D21<=$E$1,5,IF(D21<=$F$1,4,IF(D21<=$G$1,3,IF(D21<=$H$1,2,1)))) -> 2 | I21: =IF(E21<=1,1,IF(E21<=2,3,5)) -> 3 | J21: =IF(F21<=PERCENTILE($F$5:$F$917,0.2),1,IF(F21<=PERCENTILE($F$5:$F$917,0.4),2,IF(F21<=PERCENTILE($F$5:$F$917,0.6),3,IF(F21<=PERCENTILE($F$5:$F$917,0.8),4,5)))) -> 4 | K21: =H21+I21+J21 -> 9 | L21: =IF(AND(E21>=2,H21>=4),"Loyal Repeat Customers",IF(E21>=2,"At-Risk Repeat Customers",IF(AND(H21>=4,J21>=4),"Recent High-Value (One-Time)",IF(H21<=2,"Lapsed One-Time Buyers","Standard One-Time Buyers")))) -> At-Risk Repeat Customers
A22: 01927-46702-YT | B22: =INDEX(orders!$F:$F,MATCH(A22,orders!$C:$C,0)) -> Nelie Garnson | C22: =_xlfn.MAXIFS(orders!$B:$B,orders!$C:$C,A22) -> 44224 | D22: =$B$1-C22 -> 569 | E22: =COUNTIFS(orders!$C:$C,A22) -> 1 | F22: =SUMIFS(orders!$M:$M,orders!$C:$C,A22) -> 12.15 | G22: =INDEX(orders!$P:$P,MATCH(A22,orders!$C:$C,0)) -> No | H22: =IF(D22<=$E$1,5,IF(D22<=$F$1,4,IF(D22<=$G$1,3,IF(D22<=$H$1,2,1)))) -> 3 | I22: =IF(E22<=1,1,IF(E22<=2,3,5)) -> 1 | J22: =IF(F22<=PERCENTILE($F$5:$F$917,0.2),1,IF(F22<=PERCENTILE($F$5:$F$917,0.4),2,IF(F22<=PERCENTILE($F$5:$F$917,0.6),3,IF(F22<=PERCENTILE($F$5:$F$917,0.8),4,5)))) -> 1 | K22: =H22+I22+J22 -> 5 | L22: =IF(AND(E22>=2,H22>=4),"Loyal Repeat Customers",IF(E22>=2,"At-Risk Repeat Customers",IF(AND(H22>=4,J22>=4),"Recent High-Value (One-Time)",IF(H22<=2,"Lapsed One-Time Buyers","Standard One-Time Buyers")))) -> Standard One-Time Buyers
A23: 01932-87052-KO | B23: =INDEX(orders!$F:$F,MATCH(A23,orders!$C:$C,0)) -> Leonie Cullrford | C23: =_xlfn.MAXIFS(orders!$B:$B,orders!$C:$C,A23) -> 44167 | D23: =$B$1-C23 -> 626 | E23: =COUNTIFS(orders!$C:$C,A23) -> 1 | F23: =SUMIFS(orders!$M:$M,orders!$C:$C,A23) -> 24.75 | G23: =INDEX(orders!$P:$P,MATCH(A23,orders!$C:$C,0)) -> Yes | H23: =IF(D23<=$E$1,5,IF(D23<=$F$1,4,IF(D23<=$G$1,3,IF(D23<=$H$1,2,1)))) -> 3 | I23: =IF(E23<=1,1,IF(E23<=2,3,5)) -> 1 | J23: =IF(F23<=PERCENTILE($F$5:$F$917,0.2),1,IF(F23<=PERCENTILE($F$5:$F$917,0.4),2,IF(F23<=PERCENTILE($F$5:$F$917,0.6),3,IF(F23<=PERCENTILE($F$5:$F$917,0.8),4,5)))) -> 2 | K23: =H23+I23+J23 -> 6 | L23: =IF(AND(E23>=2,H23>=4),"Loyal Repeat Customers",IF(E23>=2,"At-Risk Repeat Customers",IF(AND(H23>=4,J23>=4),"Recent High-Value (One-Time)",IF(H23<=2,"Lapsed One-Time Buyers","Standard One-Time Buyers")))) -> Standard One-Time Buyers
A24: 02002-98725-CH | B24: =INDEX(orders!$F:$F,MATCH(A24,orders!$C:$C,0)) -> Alfy Snowding | C24: =_xlfn.MAXIFS(orders!$B:$B,orders!$C:$C,A24) -> 44470 | D24: =$B$1-C24 -> 323 | E24: =COUNTIFS(orders!$C:$C,A24) -> 1 | F24: =SUMIFS(orders!$M:$M,orders!$C:$C,A24) -> 58.2 | G24: =INDEX(orders!$P:$P,MATCH(A24,orders!$C:$C,0)) -> Yes | H24: =IF(D24<=$E$1,5,IF(D24<=$F$1,4,IF(D24<=$G$1,3,IF(D24<=$H$1,2,1)))) -> 4 | I24: =IF(E24<=1,1,IF(E24<=2,3,5)) -> 1 | J24: =IF(F24<=PERCENTILE($F$5:$F$917,0.2),1,IF(F24<=PERCENTILE($F$5:$F$917,0.4),2,IF(F24<=PERCENTILE($F$5:$F$917,0.6),3,IF(F24<=PERCENTILE($F$5:$F$917,0.8),4,5)))) -> 4 | K24: =H24+I24+J24 -> 9 | L24: =IF(AND(E24>=2,H24>=4),"Loyal Repeat Customers",IF(E24>=2,"At-Risk Repeat Customers",IF(AND(H24>=4,J24>=4),"Recent High-Value (One-Time)",IF(H24<=2,"Lapsed One-Time Buyers","Standard One-Time Buyers")))) -> Recent High-Value (One-Time)
A25: 02009-87294-SY | B25: =INDEX(orders!$F:$F,MATCH(A25,orders!$C:$C,0)) -> Vasily Polglase | C25: =_xlfn.MAXIFS(orders!$B:$B,orders!$C:$C,A25) -> 44085 | D25: =$B$1-C25 -> 708 | E25: =COUNTIFS(orders!$C:$C,A25) -> 1 | F25: =SUMIFS(orders!$M:$M,orders!$C:$C,A25) -> 68.75 | G25: =INDEX(orders!$P:$P,MATCH(A25,orders!$C:$C,0)) -> No | H25: =IF(D25<=$E$1,5,IF(D25<=$F$1,4,IF(D25<=$G$1,3,IF(D25<=$H$1,2,1)))) -> 3 | I25: =IF(E25<=1,1,IF(E25<=2,3,5)) -> 1 | J25: =IF(F25<=PERCENTILE($F$5:$F$917,0.2),1,IF(F25<=PERCENTILE($F$5:$F$917,0.4),2,IF(F25<=PERCENTILE($F$5:$F$917,0.6),3,IF(F25<=PERCENTILE($F$5:$F$917,0.8),4,5)))) -> 4 | K25: =H25+I25+J25 -> 8 | L25: =IF(AND(E25>=2,H25>=4),"Loyal Repeat Customers",IF(E25>=2,"At-Risk Repeat Customers",IF(AND(H25>=4,J25>=4),"Recent High-Value (One-Time)",IF(H25<=2,"Lapsed One-Time Buyers","Standard One-Time Buyers")))) -> Standard One-Time Buyers
A26: 02536-18494-AQ | B26: =INDEX(orders!$F:$F,MATCH(A26,orders!$C:$C,0)) -> Ewell Hanby | C26: =_xlfn.MAXIFS(orders!$B:$B,orders!$C:$C,A26) -> 44758 | D26: =$B$1-C26 -> 35 | E26: =COUNTIFS(orders!$C:$C,A26) -> 1 | F26: =SUMIFS(orders!$M:$M,orders!$C:$C,A26) -> 94.875 | G26: =INDEX(orders!$P:$P,MATCH(A26,orders!$C:$C,0)) -> Yes | H26: =IF(D26<=$E$1,5,IF(D26<=$F$1,4,IF(D26<=$G$1,3,IF(D26<=$H$1,2,1)))) -> 5 | I26: =IF(E26<=1,1,IF(E26<=2,3,5)) -> 1 | J26: =IF(F26<=PERCENTILE($F$5:$F$917,0.2),1,IF(F26<=PERCENTILE($F$5:$F$917,0.4),2,IF(F26<=PERCENTILE($F$5:$F$917,0.6),3,IF(F26<=PERCENTILE($F$5:$F$917,0.8),4,5)))) -> 5 | K26: =H26+I26+J26 -> 11 | L26: =IF(AND(E26>=2,H26>=4),"Loyal Repeat Customers",IF(E26>=2,"At-Risk Repeat Customers",IF(AND(H26>=4,J26>=4),"Recent High-Value (One-Time)",IF(H26<=2,"Lapsed One-Time Buyers","Standard One-Time Buyers")))) -> Recent High-Value (One-Time)
... A918: Grand Total | B918: =INDEX(orders!$F:$F,MATCH(A918,orders!$C:$C,0)) -> #N/A | C918: =_xlfn.MAXIFS(orders!$B:$B,orders!$C:$C,A918) -> 0 | D918: =$B$1-C918 -> 44793 | E918: =COUNTIFS(orders!$C:$C,A918) -> 0 | F918: =SUMIFS(orders!$M:$M,orders!$C:$C,A918) -> 0 | G918: =INDEX(orders!$P:$P,MATCH(A918,orders!$C:$C,0)) -> #N/A | H918: =IF(D918<=$E$1,5,IF(D918<=$F$1,4,IF(D918<=$G$1,3,IF(D918<=$H$1,2,1)))) -> 1 | I918: =IF(E918<=1,1,IF(E918<=2,3,5)) -> 1 | J918: =IF(F918<=PERCENTILE($F$5:$F$917,0.2),1,IF(F918<=PERCENTILE($F$5:$F$917,0.4),2,IF(F918<=PERCENTILE($F$5:$F$917,0.6),3,IF(F918<=PERCENTILE($F$5:$F$917,0.8),4,5)))) -> 1 | K918: =H918+I918+J918 -> 3 | L918: =IF(AND(E918>=2,H918>=4),"Loyal Repeat Customers",IF(E918>=2,"At-Risk Repeat Customers",IF(AND(H918>=4,J918>=4),"Recent High-Value (One-Time)",IF(H918<=2,"Lapsed One-Time Buyers","Standard One-Time Buyers")))) -> Lapsed One-Time Buyers

Sheet Total Sales
A3: Sum of Sales | C3: Coffee Type Name
A4: Years (Order Date) | B4: Months (Order Date) | C4: Arabica | D4: Excelsa | E4: Liberica | F4: Robusta | G4: Grand Total
A5: 2019 | B5: Jan | C5: 186.855 | D5: 305.97 | E5: 213.16 | F5: 123 | G5: 828.985
B6: Feb | C6: 251.965 | D6: 129.46 | E6: 434.04 | F6: 171.94 | G6: 987.405
B7: Mar | C7: 224.945 | D7: 349.12 | E7: 321.04 | F7: 126.035 | G7: 1021.14
B8: Apr | C8: 307.12 | D8: 681.075 | E8: 533.705 | F8: 158.85 | G8: 1680.75
B9: May | C9: 53.665 | D9: 83.025 | E9: 193.835 | F9: 68.04 | G9: 398.565
B10: Jun | C10: 163.02 | D10: 678.36 | E10: 171.045 | F10: 372.255 | G10: 1384.68
B11: Jul | C11: 345.02 | D11: 273.87 | E11: 184.13 | F11: 201.115 | G11: 1004.135
B12: Aug | C12: 334.89 | D12: 70.95 | E12: 134.23 | F12: 166.275 | G12: 706.345
B13: Sep | C13: 178.71 | D13: 166.1 | E13: 439.31 | F13: 492.9 | G13: 1277.02
B14: Oct | C14: 301.985 | D14: 153.765 | E14: 215.555 | F14: 213.665 | G14: 884.97
B15: Nov | C15: 312.835 | D15: 63.25 | E15: 350.895 | F15: 96.405 | G15: 823.385
B16: Dec | C16: 265.62 | D16: 526.515 | E16: 187.06 | F16: 210.59 | G16: 1189.785
A17: 2019 Total | C17: 2926.63 | D17: 3481.46 | E17: 3378.005 | F17: 2401.07 | G17: 12187.165
A18: 2020 | B18: Jan | C18: 47.25 | D18: 65.805 | E18: 274.675 | F18: 179.22 | G18: 566.95
B19: Feb | C19: 745.45 | D19: 428.885 | E19: 194.175 | F19: 429.83 | G19: 1798.34
B20: Mar | C20: 130.47 | D20: 271.485 | E20: 281.205 | F20: 231.63 | G20: 914.79
B21: Apr | C21: 27 | D21: 347.26 | E21: 147.51 | F21: 240.04 | G21: 761.81
B22: May | C22: 255.115 | D22: 541.73 | E22: 83.43 | F22: 59.08 | G22: 939.355
B23: Jun | C23: 584.79 | D23: 357.43 | E23: 355.34 | F23: 140.88 | G23: 1438.44
B24: Jul | C24: 430.62 | D24: 227.425 | E24: 236.315 | F24: 414.585 | G24: 1308.945
B25: Aug | C25: 22.5 | D25: 77.72 | E25: 60.5 | F25: 139.68 | G25: 300.4
B26: Sep | C26: 126.15 | D26: 195.11 | E26: 89.13 | F26: 302.66 | G26: 713.05
B27: Oct | C27: 376.03 | D27: 523.24 | E27: 440.965 | F27: 174.47 | G27: 1514.705
B28: Nov | C28: 515.18 | D28: 142.56 | E28: 347.04 | F28: 104.085 | G28: 1108.865
B29: Dec | C29: 95.86 | D29: 484.76 | E29: 94.17 | F29: 77.105 | G29: 751.895
A30: 2020 Total | C30: 3356.415 | D30: 3663.41 | E30: 2604.455 | F30: 2493.265 | G30: 12117.545
A31: 2021 | B31: Jan | C31: 258.345 | D31: 139.625 | E31: 279.52 | F31: 160.195 | G31: 837.685
B32: Feb | C32: 342.2 | D32: 284.25 | E32: 251.83 | F32: 80.55 | G32: 958.83
B33: Mar | C33: 418.305 | D33: 468.125 | E33: 405.055 | F33: 253.155 | G33: 1544.64
B34: Apr | C34: 102.33 | D34: 242.14 | E34: 554.875 | F34: 106.24 | G34: 1005.585
B35: May | C35: 234.72 | D35: 133.08 | E35: 267.2 | F35: 272.69 | G35: 907.69
B36: Jun | C36: 430.39 | D36: 136.205 | E36: 209.6 | F36: 88.335 | G36: 864.53
B37: Jul | C37: 109.005 | D37: 393.575 | E37: 61.035 | F37: 199.49 | G37: 763.105
B38: Aug | C38: 287.525 | D38: 288.67 | E38: 125.58 | F38: 374.135 | G38: 1075.91
B39: Sep | C39: 840.93 | D39: 409.875 | E39: 171.33 | F39: 221.44 | G39: 1643.575
B40: Oct | C40: 299.07 | D40: 260.325 | E40: 584.64 | F40: 256.365 | G40: 1400.4
B41: Nov | C41: 323.325 | D41: 565.57 | E41: 537.81 | F41: 189.475 | G41: 1616.18
B42: Dec | C42: 399.485 | D42: 148.2 | E42: 388.22 | F42: 212.075 | G42: 1147.98
...

Sheet Country BarChart
A3: Country | B3: Sum of Sales
A4: United Kingdom | B4: 2798.505
A5: Ireland | B5: 6696.865
A6: United States | B6: 35638.885
A7: Grand Total | B7: 45134.255

Sheet Country BarChart (2)
A3: Customer Name | B3: Sum of Sales
A4: Don Flintiff | B4: 278.01
A5: Nealson Cuttler | B5: 281.675
A6: Terri Farra | B6: 289.11
A7: Brenn Dundredge | B7: 307.045
A8: Allis Wilmore | B8: 317.07
A9: Grand Total | B9: 1472.91

Sheet Dashboard

Sheet Sheet1
A3: Row Labels
A4: 00246-15080-LE
A5: 00256-19905-YG
A6: 00445-42781-KX
A7: 00539-42510-RY
A8: 00852-54571-WP
A9: 00886-35803-FG
A10: 00888-74814-UZ
A11: 01035-70465-UO
A12: 01282-28364-RZ
A13: 01297-94364-XH
A14: 01304-59807-OB
... A917: Grand Total

Sheet orders
A1: Order ID | B1: Order Date | C1: Customer ID | D1: Product ID | E1: Quantity | F1: Customer Name | G1: Email | H1: Country | I1: Coffee Type | J1: Roast Type | K1: Size | L1: Unit Price | M1: Sales | N1: Coffee Type Name | O1: Roast Type Name | P1: Loyalty Card
A2: QEV-37451-860 | B2: 43713 | C2: 17670-51384-MA | D2: R-M-1 | E2: 2 | F2: =_xlfn.XLOOKUP(C2,customers!$A$1:$A$1001,customers!$B$1:$B$1001,0) -> Aloisia Allner | G2: =IF(_xlfn.XLOOKUP(C2,customers!$A$1:$A$1001,customers!$C$1:$C$1001,,0)=0,"",_xlfn.XLOOKUP(C2,customers!$A$1:$A$1001,customers!$C$1:$C$1001,,0)) -> aallner0@lulu.com | H2: =_xlfn.XLOOKUP(C2,customers!$A$1:$A$1001,customers!$G$1:$G$1001,,0) -> United States | I2: =INDEX(products!$A$1:$G$49,MATCH(orders!$D2,products!$A$1:$A$49,0),MATCH(orders!I$1,products!$A$1:$G$1,0)) -> Rob | J2: =INDEX(products!$A$1:$G$49,MATCH(orders!$D2,products!$A$1:$A$49,0),MATCH(orders!J$1,products!$A$1:$G$1,0)) -> M | K2: =INDEX(products!$A$1:$G$49,MATCH(orders!$D2,products!$A$1:$A$49,0),MATCH(orders!K$1,products!$A$1:$G$1,0)) -> 1 | L2: =INDEX(products!$A$1:$G$49,MATCH(orders!$D2,products!$A$1:$A$49,0),MATCH(orders!L$1,products!$A$1:$G$1,0)) -> 9.95 | M2: =L2*E2 -> 19.9 | N2: =IF(I2="Rob","Robusta",IF(I2="Exc","Excelsa",IF(I2="Ara","Arabica",IF(I2="Lib","Liberica","")))) -> Robusta | O2: =IF(J2="M","Medium",IF(J2="L","Light",IF(J2="D","Dark",""))) -> Medium | P2: =_xlfn.XLOOKUP(C2,customers!$A$1:$A$1001,customers!$I$1:$I$1001,,0) -> Yes
A3: QEV-37451-860 | B3: 43713 | C3: 17670-51384-MA | D3: E-M-0.5 | E3: 5 | F3: =_xlfn.XLOOKUP(C3,customers!$A$1:$A$1001,customers!$B$1:$B$1001,0) -> Aloisia Allner | G3: =IF(_xlfn.XLOOKUP(C3,customers!$A$1:$A$1001,customers!$C$1:$C$1001,,0)=0,"",_xlfn.XLOOKUP(C3,customers!$A$1:$A$1001,customers!$C$1:$C$1001,,0)) -> aallner0@lulu.com | H3: =_xlfn.XLOOKUP(C3,customers!$A$1:$A$1001,customers!$G$1:$G$1001,,0) -> United States | I3: =INDEX(products!$A$1:$G$49,MATCH(orders!$D3,products!$A$1:$A$49,0),MATCH(orders!I$1,products!$A$1:$G$1,0)) -> Exc | J3: =INDEX(products!$A$1:$G$49,MATCH(orders!$D3,products!$A$1:$A$49,0),MATCH(orders!J$1,products!$A$1:$G$1,0)) -> M | K3: =INDEX(products!$A$1:$G$49,MATCH(orders!$D3,products!$A$1:$A$49,0),MATCH(orders!K$1,products!$A$1:$G$1,0)) -> 0.5 | L3: =INDEX(products!$A$1:$G$49,MATCH(orders!$D3,products!$A$1:$A$49,0),MATCH(orders!L$1,products!$A$1:$G$1,0)) -> 8.25 | M3: =L3*E3 -> 41.25 | N3: =IF(I3="Rob","Robusta",IF(I3="Exc","Excelsa",IF(I3="Ara","Arabica",IF(I3="Lib","Liberica","")))) -> Excelsa | O3: =IF(J3="M","Medium",IF(J3="L","Light",IF(J3="D","Dark",""))) -> Medium | P3: =_xlfn.XLOOKUP(C3,customers!$A$1:$A$1001,customers!$I$1:$I$1001,,0) -> Yes
A4: FAA-43335-268 | B4: 44364 | C4: 21125-22134-PX | D4: A-L-1 | E4: 1 | F4: =_xlfn.XLOOKUP(C4,customers!$A$1:$A$1001,customers!$B$1:$B$1001,0) -> Jami Redholes | G4: =IF(_xlfn.XLOOKUP(C4,customers!$A$1:$A$1001,customers!$C$1:$C$1001,,0)=0,"",_xlfn.XLOOKUP(C4,customers!$A$1:$A$1001,customers!$C$1:$C$1001,,0)) -> jredholes2@tmall.com | H4: =_xlfn.XLOOKUP(C4,customers!$A$1:$A$1001,customers!$G$1:$G$1001,,0) -> United States | I4: =INDEX(products!$A$1:$G$49,MATCH(orders!$D4,products!$A$1:$A$49,0),MATCH(orders!I$1,products!$A$1:$G$1,0)) -> Ara | J4: =INDEX(products!$A$1:$G$49,MATCH(orders!$D4,products!$A$1:$A$49,0),MATCH(orders!J$1,products!$A$1:$G$1,0)) -> L | K4: =INDEX(products!$A$1:$G$49,MATCH(orders!$D4,products!$A$1:$A$49,0),MATCH(orders!K$1,products!$A$1:$G$1,0)) -> 1 | L4: =INDEX(products!$A$1:$G$49,MATCH(orders!$D4,products!$A$1:$A$49,0),MATCH(orders!L$1,products!$A$1:$G$1,0)) -> 12.95 | M4: =L4*E4 -> 12.95 | N4: =IF(I4="Rob","Robusta",IF(I4="Exc","Excelsa",IF(I4="Ara","Arabica",IF(I4="Lib","Liberica","")))) -> Arabica | O4: =IF(J4="M","Medium",IF(J4="L","Light",IF(J4="D","Dark",""))) -> Light | P4: =_xlfn.XLOOKUP(C4,customers!$A$1:$A$1001,customers!$I$1:$I$1001,,0) -> Yes
A5: KAC-83089-793 | B5: 44392 | C5: 23806-46781-OU | D5: E-M-1 | E5: 2 | F5: =_xlfn.XLOOKUP(C5,customers!$A$1:$A$1001,customers!$B$1:$B$1001,0) -> Christoffer O' Shea | G5: =IF(_xlfn.XLOOKUP(C5,customers!$A$1:$A$1001,customers!$C$1:$C$1001,,0)=0,"",_xlfn.XLOOKUP(C5,customers!$A$1:$A$1001,customers!$C$1:$C$1001,,0)) | H5: =_xlfn.XLOOKUP(C5,customers!$A$1:$A$1001,customers!$G$1:$G$1001,,0) -> Ireland | I5: =INDEX(products!$A$1:$G$49,MATCH(orders!$D5,products!$A$1:$A$49,0),MATCH(orders!I$1,products!$A$1:$G$1,0)) -> Exc | J5: =INDEX(products!$A$1:$G$49,MATCH(orders!$D5,products!$A$1:$A$49,0),MATCH(orders!J$1,products!$A$1:$G$1,0)) -> M | K5: =INDEX(products!$A$1:$G$49,MATCH(orders!$D5,products!$A$1:$A$49,0),MATCH(orders!K$1,products!$A$1:$G$1,0)) -> 1 | L5: =INDEX(products!$A$1:$G$49,MATCH(orders!$D5,products!$A$1:$A$49,0),MATCH(orders!L$1,products!$A$1:$G$1,0)) -> 13.75 | M5: =L5*E5 -> 27.5 | N5: =IF(I5="Rob","Robusta",IF(I5="Exc","Excelsa",IF(I5="Ara","Arabica",IF(I5="Lib","Liberica","")))) -> Excelsa | O5: =IF(J5="M","Medium",IF(J5="L","Light",IF(J5="D","Dark",""))) -> Medium | P5: =_xlfn.XLOOKUP(C5,customers!$A$1:$A$1001,customers!$I$1:$I$1001,,0) -> No
A6: KAC-83089-793 | B6: 44392 | C6: 23806-46781-OU | D6: R-L-2.5 | E6: 2 | F6: =_xlfn.XLOOKUP(C6,customers!$A$1:$A$1001,customers!$B$1:$B$1001,0) -> Christoffer O' Shea | G6: =IF(_xlfn.XLOOKUP(C6,customers!$A$1:$A$1001,customers!$C$1:$C$1001,,0)=0,"",_xlfn.XLOOKUP(C6,customers!$A$1:$A$1001,customers!$C$1:$C$1001,,0)) | H6: =_xlfn.XLOOKUP(C6,customers!$A$1:$A$1001,customers!$G$1:$G$1001,,0) -> Ireland | I6: =INDEX(products!$A$1:$G$49,MATCH(orders!$D6,products!$A$1:$A$49,0),MATCH(orders!I$1,products!$A$1:$G$1,0)) -> Rob | J6: =INDEX(products!$A$1:$G$49,MATCH(orders!$D6,products!$A$1:$A$49,0),MATCH(orders!J$1,products!$A$1:$G$1,0)) -> L | K6: =INDEX(products!$A$1:$G$49,MATCH(orders!$D6,products!$A$1:$A$49,0),MATCH(orders!K$1,products!$A$1:$G$1,0)) -> 2.5 | L6: =INDEX(products!$A$1:$G$49,MATCH(orders!$D6,products!$A$1:$A$49,0),MATCH(orders!L$1,products!$A$1:$G$1,0)) -> 27.485 | M6: =L6*E6 -> 54.97 | N6: =IF(I6="Rob","Robusta",IF(I6="Exc","Excelsa",IF(I6="Ara","Arabica",IF(I6="Lib","Liberica","")))) -> Robusta | O6: =IF(J6="M","Medium",IF(J6="L","Light",IF(J6="D","Dark",""))) -> Light | P6: =_xlfn.XLOOKUP(C6,customers!$A$1:$A$1001,customers!$I$1:$I$1001,,0) -> No
A7: CVP-18956-553 | B7: 44412 | C7: 86561-91660-RB | D7: L-D-1 | E7: 3 | F7: =_xlfn.XLOOKUP(C7,customers!$A$1:$A$1001,customers!$B$1:$B$1001,0) -> Beryle Cottier | G7: =IF(_xlfn.XLOOKUP(C7,customers!$A$1:$A$1001,customers!$C$1:$C$1001,,0)=0,"",_xlfn.XLOOKUP(C7,customers!$A$1:$A$1001,customers!$C$1:$C$1001,,0)) | H7: =_xlfn.XLOOKUP(C7,customers!$A$1:$A$1001,customers!$G$1:$G$1001,,0) -> United States | I7: =INDEX(products!$A$1:$G$49,MATCH(orders!$D7,products!$A$1:$A$49,0),MATCH(orders!I$1,products!$A$1:$G$1,0)) -> Lib | J7: =INDEX(products!$A$1:$G$49,MATCH(orders!$D7,products!$A$1:$A$49,0),MATCH(orders!J$1,products!$A$1:$G$1,0)) -> D | K7: =INDEX(products!$A$1:$G$49,MATCH(orders!$D7,products!$A$1:$A$49,0),MATCH(orders!K$1,products!$A$1:$G$1,0)) -> 1 | L7: =INDEX(products!$A$1:$G$49,MATCH(orders!$D7,products!$A$1:$A$49,0),MATCH(orders!L$1,products!$A$1:$G$1,0)) -> 12.95 | M7: =L7*E7 -> 38.85 | N7: =IF(I7="Rob","Robusta",IF(I7="Exc","Excelsa",IF(I7="Ara","Arabica",IF(I7="Lib","Liberica","")))) -> Liberica | O7: =IF(J7="M","Medium",IF(J7="L","Light",IF(J7="D","Dark",""))) -> Dark | P7: =_xlfn.XLOOKUP(C7,customers!$A$1:$A$1001,customers!$I$1:$I$1001,,0) -> No
A8: IPP-31994-879 | B8: 44582 | C8: 65223-29612-CB | D8: E-D-0.5 | E8: 3 | F8: =_xlfn.XLOOKUP(C8,customers!$A$1:$A$1001,customers!$B$1:$B$1001,0) -> Shaylynn Lobe | G8: =IF(_xlfn.XLOOKUP(C8,customers!$A$1:$A$1001,customers!$C$1:$C$1001,,0)=0,"",_xlfn.XLOOKUP(C8,customers!$A$1:$A$1001,customers!$C$1:$C$1001,,0)) -> slobe6@nifty.com | H8: =_xlfn.XLOOKUP(C8,customers!$A$1:$A$1001,customers!$G$1:$G$1001,,0) -> United States | I8: =INDEX(products!$A$1:$G$49,MATCH(orders!$D8,products!$A$1:$A$49,0),MATCH(orders!I$1,products!$A$1:$G$1,0)) -> Exc | J8: =INDEX(products!$A$1:$G$49,MATCH(orders!$D8,products!$A$1:$A$49,0),MATCH(orders!J$1,products!$A$1:$G$1,0)) -> D | K8: =INDEX(products!$A$1:$G$49,MATCH(orders!$D8,products!$A$1:$A$49,0),MATCH(orders!K$1,products!$A$1:$G$1,0)) -> 0.5 | L8: =INDEX(products!$A$1:$G$49,MATCH(orders!$D8,products!$A$1:$A$49,0),MATCH(orders!L$1,products!$A$1:$G$1,0)) -> 7.29 | M8: =L8*E8 -> 21.87 | N8: =IF(I8="Rob","Robusta",IF(I8="Exc","Excelsa",IF(I8="Ara","Arabica",IF(I8="Lib","Liberica","")))) -> Excelsa | O8: =IF(J8="M","Medium",IF(J8="L","Light",IF(J8="D","Dark",""))) -> Dark | P8: =_xlfn.XLOOKUP(C8,customers!$A$1:$A$1001,customers!$I$1:$I$1001,,0) -> Yes
A9: SNZ-65340-705 | B9: 44701 | C9: 21134-81676-FR | D9: L-L-0.2 | E9: 1 | F9: =_xlfn.XLOOKUP(C9,customers!$A$1:$A$1001,customers!$B$1:$B$1001,0) -> Melvin Wharfe | G9: =IF(_xlfn.XLOOKUP(C9,customers!$A$1:$A$1001,customers!$C$1:$C$1001,,0)=0,"",_xlfn.XLOOKUP(C9,customers!$A$1:$A$1001,customers!$C$1:$C$1001,,0)) | H9: =_xlfn.XLOOKUP(C9,customers!$A$1:$A$1001,customers!$G$1:$G$1001,,0) -> Ireland | I9: =INDEX(products!$A$1:$G$49,MATCH(orders!$D9,products!$A$1:$A$49,0),MATCH(orders!I$1,products!$A$1:$G$1,0)) -> Lib | J9: =INDEX(products!$A$1:$G$49,MATCH(orders!$D9,products!$A$1:$A$49,0),MATCH(orders!J$1,products!$A$1:$G$1,0)) -> L | K9: =INDEX(products!$A$1:$G$49,MATCH(orders!$D9,products!$A$1:$A$49,0),MATCH(orders!K$1,products!$A$1:$G$1,0)) -> 0.2 | L9: =INDEX(products!$A$1:$G$49,MATCH(orders!$D9,products!$A$1:$A$49,0),MATCH(orders!L$1,products!$A$1:$G$1,0)) -> 4.755 | M9: =L9*E9 -> 4.755 | N9: =IF(I9="Rob","Robusta",IF(I9="Exc","Excelsa",IF(I9="Ara","Arabica",IF(I9="Lib","Liberica","")))) -> Liberica | O9: =IF(J9="M","Medium",IF(J9="L","Light",IF(J9="D","Dark",""))) -> Light | P9: =_xlfn.XLOOKUP(C9,customers!$A$1:$A$1001,customers!$I$1:$I$1001,,0) -> Yes
A10: EZT-46571-659 | B10: 43467 | C10: 03396-68805-ZC | D10: R-M-0.5 | E10: 3 | F10: =_xlfn.XLOOKUP(C10,customers!$A$1:$A$1001,customers!$B$1:$B$1001,0) -> Guthrey Petracci | G10: =IF(_xlfn.XLOOKUP(C10,customers!$A$1:$A$1001,customers!$C$1:$C$1001,,0)=0,"",_xlfn.XLOOKUP(C10,customers!$A$1:$A$1001,customers!$C$1:$C$1001,,0)) -> gpetracci8@livejournal.com | H10: =_xlfn.XLOOKUP(C10,customers!$A$1:$A$1001,customers!$G$1:$G$1001,,0) -> United States | I10: =INDEX(products!$A$1:$G$49,MATCH(orders!$D10,products!$A$1:$A$49,0),MATCH(orders!I$1,products!$A$1:$G$1,0)) -> Rob | J10: =INDEX(products!$A$1:$G$49,MATCH(orders!$D10,products!$A$1:$A$49,0),MATCH(orders!J$1,products!$A$1:$G$1,0)) -> M | K10: =INDEX(products!$A$1:$G$49,MATCH(orders!$D10,products!$A$1:$A$49,0),MATCH(orders!K$1,products!$A$1:$G$1,0)) -> 0.5 | L10: =INDEX(products!$A$1:$G$49,MATCH(orders!$D10,products!$A$1:$A$49,0),MATCH(orders!L$1,products!$A$1:$G$1,0)) -> 5.97 | M10: =L10*E10 -> 17.91 | N10: =IF(I10="Rob","Robusta",IF(I10="Exc","Excelsa",IF(I10="Ara","Arabica",IF(I10="Lib","Liberica","")))) -> Robusta | O10: =IF(J10="M","Medium",IF(J10="L","Light",IF(J10="D","Dark",""))) -> Medium | P10: =_xlfn.XLOOKUP(C10,customers!$A$1:$A$1001,customers!$I$1:$I$1001,,0) -> No
A11: NWQ-70061-912 | B11: 43713 | C11: 61021-27840-ZN | D11: R-M-0.5 | E11: 1 | F11: =_xlfn.XLOOKUP(C11,customers!$A$1:$A$1001,customers!$B$1:$B$1001,0) -> Rodger Raven | G11: =IF(_xlfn.XLOOKUP(C11,customers!$A$1:$A$1001,customers!$C$1:$C$1001,,0)=0,"",_xlfn.XLOOKUP(C11,customers!$A$1:$A$1001,customers!$C$1:$C$1001,,0)) -> rraven9@ed.gov | H11: =_xlfn.XLOOKUP(C11,customers!$A$1:$A$1001,customers!$G$1:$G$1001,,0) -> United States | I11: =INDEX(products!$A$1:$G$49,MATCH(orders!$D11,products!$A$1:$A$49,0),MATCH(orders!I$1,products!$A$1:$G$1,0)) -> Rob | J11: =INDEX(products!$A$1:$G$49,MATCH(orders!$D11,products!$A$1:$A$49,0),MATCH(orders!J$1,products!$A$1:$G$1,0)) -> M | K11: =INDEX(products!$A$1:$G$49,MATCH(orders!$D11,products!$A$1:$A$49,0),MATCH(orders!K$1,products!$A$1:$G$1,0)) -> 0.5 | L11: =INDEX(products!$A$1:$G$49,MATCH(orders!$D11,products!$A$1:$A$49,0),MATCH(orders!L$1,products!$A$1:$G$1,0)) -> 5.97 | M11: =L11*E11 -> 5.97 | N11: =IF(I11="Rob","Robusta",IF(I11="Exc","Excelsa",IF(I11="Ara","Arabica",IF(I11="Lib","Liberica","")))) -> Robusta | O11: =IF(J11="M","Medium",IF(J11="L","Light",IF(J11="D","Dark",""))) -> Medium | P11: =_xlfn.XLOOKUP(C11,customers!$A$1:$A$1001,customers!$I$1:$I$1001,,0) -> No
A12: BKK-47233-845 | B12: 44263 | C12: 76239-90137-UQ | D12: A-D-1 | E12: 4 | F12: =_xlfn.XLOOKUP(C12,customers!$A$1:$A$1001,customers!$B$1:$B$1001,0) -> Ferrell Ferber | G12: =IF(_xlfn.XLOOKUP(C12,customers!$A$1:$A$1001,customers!$C$1:$C$1001,,0)=0,"",_xlfn.XLOOKUP(C12,customers!$A$1:$A$1001,customers!$C$1:$C$1001,,0)) -> fferbera@businesswire.com | H12: =_xlfn.XLOOKUP(C12,customers!$A$1:$A$1001,customers!$G$1:$G$1001,,0) -> United States | I12: =INDEX(products!$A$1:$G$49,MATCH(orders!$D12,products!$A$1:$A$49,0),MATCH(orders!I$1,products!$A$1:$G$1,0)) -> Ara | J12: =INDEX(products!$A$1:$G$49,MATCH(orders!$D12,products!$A$1:$A$49,0),MATCH(orders!J$1,products!$A$1:$G$1,0)) -> D | K12: =INDEX(products!$A$1:$G$49,MATCH(orders!$D12,products!$A$1:$A$49,0),MATCH(orders!K$1,products!$A$1:$G$1,0)) -> 1 | L12: =INDEX(products!$A$1:$G$49,MATCH(orders!$D12,products!$A$1:$A$49,0),MATCH(orders!L$1,products!$A$1:$G$1,0)) -> 9.95 | M12: =L12*E12 -> 39.8 | N12: =IF(I12="Rob","Robusta",IF(I12="Exc","Excelsa",IF(I12="Ara","Arabica",IF(I12="Lib","Liberica","")))) -> Arabica | O12: =IF(J12="M","Medium",IF(J12="L","Light",IF(J12="D","Dark",""))) -> Dark | P12: =_xlfn.XLOOKUP(C12,customers!$A$1:$A$1001,customers!$I$1:$I$1001,,0) -> No
A13: VQR-01002-970 | B13: 44132 | C13: 49315-21985-BB | D13: E-L-2.5 | E13: 5 | F13: =_xlfn.XLOOKUP(C13,customers!$A$1:$A$1001,customers!$B$1:$B$1001,0) -> Duky Phizackerly | G13: =IF(_xlfn.XLOOKUP(C13,customers!$A$1:$A$1001,customers!$C$1:$C$1001,,0)=0,"",_xlfn.XLOOKUP(C13,customers!$A$1:$A$1001,customers!$C$1:$C$1001,,0)) -> dphizackerlyb@utexas.edu | H13: =_xlfn.XLOOKUP(C13,customers!$A$1:$A$1001,customers!$G$1:$G$1001,,0) -> United States | I13: =INDEX(products!$A$1:$G$49,MATCH(orders!$D13,products!$A$1:$A$49,0),MATCH(orders!I$1,products!$A$1:$G$1,0)) -> Exc | J13: =INDEX(products!$A$1:$G$49,MATCH(orders!$D13,products!$A$1:$A$49,0),MATCH(orders!J$1,products!$A$1:$G$1,0)) -> L | K13: =INDEX(products!$A$1:$G$49,MATCH(orders!$D13,products!$A$1:$A$49,0),MATCH(orders!K$1,products!$A$1:$G$1,0)) -> 2.5 | L13: =INDEX(products!$A$1:$G$49,MATCH(orders!$D13,products!$A$1:$A$49,0),MATCH(orders!L$1,products!$A$1:$G$1,0)) -> 34.155 | M13: =L13*E13 -> 170.775 | N13: =IF(I13="Rob","Robusta",IF(I13="Exc","Excelsa",IF(I13="Ara","Arabica",IF(I13="Lib","Liberica","")))) -> Excelsa | O13: =IF(J13="M","Medium",IF(J13="L","Light",IF(J13="D","Dark",""))) -> Light | P13: =_xlfn.XLOOKUP(C13,customers!$A$1:$A$1001,customers!$I$1:$I$1001,,0) -> Yes
... A1001: IRV-20769-219 | B1001: 44119 | C1001: 77131-58092-GE | D1001: E-M-0.2 | E1001: 3 | F1001: =_xlfn.XLOOKUP(C1001,customers!$A$1:$A$1001,customers!$B$1:$B$1001,0) -> Vidovic Antonelli | G1001: =IF(_xlfn.XLOOKUP(C1001,customers!$A$1:$A$1001,customers!$C$1:$C$1001,,0)=0,"",_xlfn.XLOOKUP(C1001,customers!$A$1:$A$1001,customers!$C$1:$C$1001,,0)) | H1001: =_xlfn.XLOOKUP(C1001,customers!$A$1:$A$1001,customers!$G$1:$G$1001,,0) -> United Kingdom | I1001: =INDEX(products!$A$1:$G$49,MATCH(orders!$D1001,products!$A$1:$A$49,0),MATCH(orders!I$1,products!$A$1:$G$1,0)) -> Exc | J1001: =INDEX(products!$A$1:$G$49,MATCH(orders!$D1001,products!$A$1:$A$49,0),MATCH(orders!J$1,products!$A$1:$G$1,0)) -> M | K1001: =INDEX(products!$A$1:$G$49,MATCH(orders!$D1001,products!$A$1:$A$49,0),MATCH(orders!K$1,products!$A$1:$G$1,0)) -> 0.2 | L1001: =INDEX(products!$A$1:$G$49,MATCH(orders!$D1001,products!$A$1:$A$49,0),MATCH(orders!L$1,products!$A$1:$G$1,0)) -> 4.125 | M1001: =L1001*E1001 -> 12.375 | N1001: =IF(I1001="Rob","Robusta",IF(I1001="Exc","Excelsa",IF(I1001="Ara","Arabica",IF(I1001="Lib","Liberica","")))) -> Excelsa | O1001: =IF(J1001="M","Medium",IF(J1001="L","Light",IF(J1001="D","Dark",""))) -> Medium | P1001: =_xlfn.XLOOKUP(C1001,customers!$A$1:$A$1001,customers!$I$1:$I$1001,,0) -> Yes

Sheet customers
A1: Customer ID | B1: Customer Name | C1: Email | D1: Phone Number | E1: Address Line 1 | F1: City | G1: Country | H1: Postcode | I1: Loyalty Card
A2: 17670-51384-MA | B2: Aloisia Allner | C2: aallner0@lulu.com | D2: +1 (862) 817-0124 | E2: 57999 Pepper Wood Alley | F2: Paterson | G2: United States | H2: 7505 | I2: Yes
A3: 73342-18763-UW | B3: Piotr Bote | C3: pbote1@yelp.com | D3: +353 (913) 396-4653 | E3: 2112 Ridgeway Hill | F3: Crumlin | G3: Ireland | H3: D6W | I3: No
A4: 21125-22134-PX | B4: Jami Redholes | C4: jredholes2@tmall.com | D4: +1 (210) 986-6806 | E4: 5214 Bartillon Park | F4: San Antonio | G4: United States | H4: 78205 | I4: Yes
A5: 71253-00052-RN | B5: Dene Azema | C5: dazema3@facebook.com | D5: +1 (217) 418-0714 | E5: 27 Maywood Place | F5: Springfield | G5: United States | H5: 62711 | I5: Yes
A6: 23806-46781-OU | B6: Christoffer O' Shea | D6: +353 (698) 362-9201 | E6: 38980 Manitowish Junction | F6: Cill Airne | G6: Ireland | H6: N41 | I6: No
A7: 86561-91660-RB | B7: Beryle Cottier | D7: +1 (570) 289-7473 | E7: 2651 Stoughton Place | F7: Scranton | G7: United States | H7: 18505 | I7: No
A8: 65223-29612-CB | B8: Shaylynn Lobe | C8: slobe6@nifty.com | D8: +1 (937) 954-4541 | E8: 7005 Mariners Cove Place | F8: Dayton | G8: United States | H8: 45440 | I8: Yes
A9: 21134-81676-FR | B9: Melvin Wharfe | D9: +353 (507) 574-3034 | E9: 7 Straubel Road | F9: Kill | G9: Ireland | H9: P24 | I9: Yes
A10: 03396-68805-ZC | B10: Guthrey Petracci | C10: gpetracci8@livejournal.com | D10: +1 (310) 868-1842 | E10: 949 Paget Parkway | F10: Los Angeles | G10: United States | H10: 90045 | I10: No
A11: 61021-27840-ZN | B11: Rodger Raven | C11: rraven9@ed.gov | D11: +1 (213) 263-0288 | E11: 1 Reinke Avenue | F11: Los Angeles | G11: United States | H11: 90065 | I11: No
A12: 76239-90137-UQ | B12: Ferrell Ferber | C12: fferbera@businesswire.com | D12: +1 (408) 383-5302 | E12: 68 High Crossing Court | F12: San Jose | G12: United States | H12: 95160 | I12: No
A13: 49315-21985-BB | B13: Duky Phizackerly | C13: dphizackerlyb@utexas.edu | D13: +1 (408) 533-6012 | E13: 28643 Bluejay Crossing | F13: San Jose | G13: United States | H13: 95194 | I13: Yes
A14: 34136-36674-OM | B14: Rosaleen Scholar | C14: rscholarc@nyu.edu | D14: +1 (804) 420-0420 | E14: 80915 Montana Park | F14: Richmond | G14: United States | H14: 23285 | I14: No
A15: 39396-12890-PE | B15: Terence Vanyutin | C15: tvanyutind@wix.com | E15: 331 Bunting Hill | F15: Migrate | G15: United States | H15: 41905 | I15: No
A16: 95875-73336-RG | B16: Patrice Trobe | C16: ptrobee@wunderground.com | D16: +1 (314) 240-7896 | E16: 827 Declaration Plaza | F16: Saint Louis | G16: United States | H16: 63131 | I16: Yes
A17: 25473-43727-BY | B17: Llywellyn Oscroft | C17: loscroftf@ebay.co.uk | E17: 022 Roth Place | F17: Philadelphia | G17: United States | H17: 19172 | I17: No
A18: 99643-51048-IQ | B18: Minni Alabaster | C18: malabasterg@hexun.com | D18: +1 (971) 483-6255 | E18: 3 Charing Cross Trail | F18: Portland | G18: United States | H18: 97271 | I18: No
A19: 62173-15287-CU | B19: Rhianon Broxup | C19: rbroxuph@jimdo.com | D19: +1 (713) 663-1338 | E19: 83517 Thierer Court | F19: Houston | G19: United States | H19: 77240 | I19: No
A20: 57611-05522-ST | B20: Pall Redford | C20: predfordi@ow.ly | E20: 7337 Hayes Junction | F20: Caherconlish | G20: Ireland | H20: F45 | I20: Yes
A21: 76664-37050-DT | B21: Aurea Corradino | C21: acorradinoj@harvard.edu | D21: +1 (646) 202-5965 | E21: 698 Canary Terrace | F21: New York City | G21: United States | H21: 10060 | I21: Yes
A22: 84565-53984-SX | B22: Kendal Scardefield | D22: +353 (733) 405-3302 | E22: 3 Northridge Crossing | F22: Clondalkin | G22: Ireland | H22: D24 | I22: Yes
A23: 03090-88267-BQ | B23: Avrit Davidowsky | C23: adavidowskyl@netvibes.com | D23: +1 (616) 481-9962 | E23: 9 Warrior Junction | F23: Grand Rapids | G23: United States | H23: 49560 | I23: No
A24: 37651-47492-NC | B24: Annabel Antuk | C24: aantukm@kickstarter.com | D24: +1 (941) 740-6268 | E24: 77965 Lawn Park | F24: Punta Gorda | G24: United States | H24: 33982 | I24: Yes
A25: 95399-57205-HI | B25: Iorgo Kleinert | C25: ikleinertn@timesonline.co.uk | D25: +1 (360) 352-6598 | E25: 1 Morningstar Lane | F25: Vancouver | G25: United States | H25: 98682 | I25: Yes
A26: 24010-66714-HW | B26: Chrisy Blofeld | C26: cblofeldo@amazon.co.uk | D26: +1 (303) 936-3357 | E26: 013 Talisman Terrace | F26: Englewood | G26: United States | H26: 80150 | I26: No
A27: 07591-92789-UA | B27: Culley Farris | D27: +1 (941) 267-4822 | E27: 4 Mitchell Drive | F27: Punta Gorda | G27: United States | H27: 33982 | I27: Yes
A28: 49231-44455-IC | B28: Selene Shales | C28: sshalesq@umich.edu | D28: +1 (707) 881-5004 | E28: 74 Bultman Plaza | F28: Petaluma | G28: United States | H28: 94975 | I28: Yes
A29: 50124-88608-EO | B29: Vivie Danneil | C29: vdanneilr@mtv.com | D29: +353 (751) 346-0399 | E29: 5626 Darwin Avenue | F29: Tralee | G29: Ireland | H29: V92 | I29: No
A30: 00888-74814-UZ | B30: Theresita Newbury | C30: tnewburys@usda.gov | D30: +353 (803) 587-0026 | E30: 79526 Bultman Lane | F30: Clonskeagh | G30: Ireland | H30: D04 | I30: No
A31: 14158-30713-OB | B31: Mozelle Calcutt | C31: mcalcuttt@baidu.com | D31: +353 (928) 869-1762 | E31: 4389 Russell Way | F31: Rathwire | G31: Ireland | H31: Y25 | I31: Yes
A32: 51427-89175-QJ | B32: Adrian Swaine | D32: +1 (303) 486-9517 | E32: 95 Straubel Hill | F32: Aurora | G32: United States | H32: 80044 | I32: No
A33: 52082-49024-ON | B33: Ray Leivesley | C33: rleivesleyv@canalblog.com | D33: +1 (212) 535-7791 | E33: 91 Stephen Drive | F33: Jamaica | G33: United States | H33: 11407 | I33: No
A34: 04540-43685-DV | B34: Nelly Basezzi | C34: nbasezziw@webeden.co.uk | D34: +353 (125) 815-7345 | E34: 923 Mallard Junction | F34: Bailieborough | G34: Ireland | H34: C15 | I34: Yes
A35: 39123-12846-YJ | B35: Gallard Gatheral | C35: ggatheralx@123-reg.co.uk | E35: 40 Clemons Place | F35: Grand Forks | G35: United States | H35: 58207 | I35: No
A36: 44981-99666-XB | B36: Una Welberry | C36: uwelberryy@ebay.co.uk | D36: +44 (392) 503-8132 | E36: 40915 Schlimgen Park | F36: Upton | G36: United Kingdom | H36: DN21 | I36: Yes
A37: 24825-51803-CQ | B37: Faber Eilhart | C37: feilhartz@who.int | D37: +1 (304) 510-6095 | E37: 6966 Victoria Street | F37: Charleston | G37: United States | H37: 25362 | I37: No
A38: 77634-13918-GJ | B38: Zorina Ponting | C38: zponting10@altervista.org | D38: +1 (501) 172-1476 | E38: 7118 Holmberg Court | F38: Little Rock | G38: United States | H38: 72204 | I38: No
A39: 13694-25001-LX | B39: Silvio Strase | C39: sstrase11@booking.com | D39: +1 (303) 579-8015 | E39: 5 Forest Lane | F39: Denver | G39: United States | H39: 80291 | I39: No
A40: 08523-01791-TI | B40: Dorie de la Tremoille | C40: dde12@unesco.org | D40: +1 (612) 492-5160 | E40: 0817 Dennis Street | F40: Minneapolis | G40: United States | H40: 55458 | I40: No
...

Sheet products
A1: Product ID | B1: Coffee Type | C1: Roast Type | D1: Size | E1: Unit Price | F1: Price per 100g | G1: Profit
A2: A-L-0.2 | B2: Ara | C2: L | D2: 0.2 | E2: 3.885 | F2: 1.9425 | G2: 0.34965
A3: A-L-0.5 | B3: Ara | C3: L | D3: 0.5 | E3: 7.77 | F3: 1.554 | G3: 0.6993
A4: A-L-1 | B4: Ara | C4: L | D4: 1 | E4: 12.95 | F4: 1.295 | G4: 1.1655
A5: A-L-2.5 | B5: Ara | C5: L | D5: 2.5 | E5: 29.785 | F5: 1.1914 | G5: 2.68065
A6: A-M-0.2 | B6: Ara | C6: M | D6: 0.2 | E6: 3.375 | F6: 1.6875 | G6: 0.30375
A7: A-M-0.5 | B7: Ara | C7: M | D7: 0.5 | E7: 6.75 | F7: 1.35 | G7: 0.6075
A8: A-M-1 | B8: Ara | C8: M | D8: 1 | E8: 11.25 | F8: 1.125 | G8: 1.0125
A9: A-M-2.5 | B9: Ara | C9: M | D9: 2.5 | E9: 25.875 | F9: 1.035 | G9: 2.32875
A10: A-D-0.2 | B10: Ara | C10: D | D10: 0.2 | E10: 2.985 | F10: 1.4925 | G10: 0.26865
A11: A-D-0.5 | B11: Ara | C11: D | D11: 0.5 | E11: 5.97 | F11: 1.194 | G11: 0.5373
A12: A-D-1 | B12: Ara | C12: D | D12: 1 | E12: 9.95 | F12: 0.995 | G12: 0.8955
A13: A-D-2.5 | B13: Ara | C13: D | D13: 2.5 | E13: 22.885 | F13: 0.9154 | G13: 2.05965
... A49: E-D-2.5 | B49: Exc | C49: D | D49: 2.5 | E49: 27.945 | F49: 1.1178 | G49: 3.07395
